Workbook
Name Slicer_Bo_lim: #N/A
Name Slicer_Ish_formati: #N/A

Sheet Dashboard
C1: NAVBAHOR GROUP - Xodimlar almashinuvi
J3: Holat: 30.09.2026 | 800 xodim, 7 bo’lim
C5: Jami xodim | F5: Ketganlar soni | I5: Ketish foizi | L5: O'rtacha oylik (so'm)
C6: =GETPIVOTDATA("Xodim_ID",Pivots!$I$23) -> 800 | F6: =GETPIVOTDATA("Xodim_ID",Pivots!$A$38) -> 143 | I6: =GETPIVOTDATA("Average of Ishdan_ketganlar",Pivots!$A$16) -> 0.17875 | L6: =GETPIVOTDATA("Oylik (so'm)",Pivots!$A$51) -> 7168621.6

Sheet Pivots
A3: Ishdan ketish foizi
A4: Row Labels | B4: Ishdan ketish foizi
A5: MIJOZLAR XIZMATI | B5: 0.23232323 | J5: mamnunlik bahosi
A6: SOTUV | B6: 0.18918919 | I6: Row Labels | J6: Average of Ishdan_ketganlar
A7: MOLIYA | B7: 0.17391304 | I7: 1 | J7: 0.35483871
A8: IT | B8: 0.16393443 | I8: 2 | J8: 0.28767123
A9: LOGISTIKA | B9: 0.16363636 | I9: 3 | J9: 0.1625
A10: MARKETING | B10: 0.10843373 | I10: 4 | J10: 0.095238095
A11: HR | B11: 0.090909091 | I11: 5 | J11: 0.16
A12: Grand Total | B12: 0.17875 | I12: Grand Total | J12: 0.17875
A15: Bo'lim bo'yicha ketishlar
A16: Row Labels | B16: Average of Ishdan_ketganlar
A17: MIJOZLAR XIZMATI | B17: 0.23232323
A18: SOTUV | B18: 0.18918919
A19: MOLIYA | B19: 0.17391304
A20: IT | B20: 0.16393443
A21: LOGISTIKA | B21: 0.16363636
A22: MARKETING | B22: 0.10843373
A23: HR | B23: 0.090909091 | I23: Row Labels | J23: Count of Xodim_ID
A24: Grand Total | B24: 0.17875 | I24: HR | J24: 33
I25: IT | J25: 122
I26: LOGISTIKA | J26: 110
I27: MARKETING | J27: 83
A28: staj guruhi bo'yicha | I28: MIJOZLAR XIZMATI | J28: 198
A29: Row Labels | B29: Ishdan_ketganlar1 | I29: MOLIYA | J29: 69
A30: 1 yildan kam | B30: 0.24875622 | I30: SOTUV | J30: 185
A31: 1-3 yil | B31: 0.18316832 | I31: Grand Total | J31: 800
A32: 3 yildan ko'p | B32: 0.14105793
A33: Grand Total | B33: 0.17875
A36: Ishdan_ketgan | B36: (All)
A37: ishdan ketish sababi
A38: Row Labels | B38: Count of Xodim_ID
A39: Shaxsiy sabab | B39: 10
A40: Boshqa kompaniyaga o'tdi | B40: 11
A41: Boshqa shaharga ko'chdi | B41: 14
A42: Ish yuklamasi ko'p | B42: 22
A43: Maosh past | B43: 27
A44: Rahbar bilan muammo | B44: 29
A45: Karyera o'sishi yo'q | B45: 30
A46: Grand Total | B46: 143
...

Sheet HR_Clean
A1: Xodim_ID | B1: Ism_familiya | C1: Jins | D1: Tug'ilgan_sana | E1: Ishga_kirgan_sana | F1: Bo'lim | G1: Lavozim | H1: Daraja | I1: Shahar | J1: Oylik (so'm) | K1: Samaradorlik_bahosi (1-5) | L1: Mamnunlik_bahosi (1-5) | M1: Qo'shimcha_ish_soati (oyiga) | N1: Ish_formati | O1: Ta'lim | P1: Ishdan_ketgan | Q1: Ketgan_sana | R1: Ketish_sababi | S1: Yosh | T1: Staj_yil | U1: Bo'lim_rahbari | V1: Ishdan_ketganlar | W1: staj_guruhi
A2: EMP-0539 | B2: Gulnora Mirzayeva | C2: Ayol | D2: 37053 | E2: 44782 | F2: IT | G2: Tizim administratori | H2: Senior | I2: Samarqand | J2: 21690000 | K2: 4 | L2: 4 | M2: 0 | N2: Ofis | O2: O'rta maxsus | P2: Yo'q | S2: =DATEDIF(D2,DATE(2026,9,30),"Y") -> 25 | T2: =(IF(Q2="",DATE(2026,9,30),Q2)-E2)/365.25 -> 4.1423682 | U2: =_xlfn.XLOOKUP(Table1_1[[#This Row],[Bo''lim]],Bolimlar!A:A,Bolimlar!B:B,"Topilmadi") -> Jasur Yusupov | V2: =IF(P2="Ha",1,0) -> 0 | W2: =IF(T2<1,"1 yildan kam",IF(T2<3,"1-3 yil","3 yildan ko'p")) -> 3 yildan ko'p
A3: EMP-0791 | B3: Zilola Umarova | C3: Ayol | D3: 32574 | E3: 43335 | F3: IT | G3: Dasturchi | H3: Senior | I3: Farg'ona | J3: 21490000 | K3: 2 | L3: 2 | M3: 5 | N3: Ofis | O3: Bakalavr | P3: Yo'q | S3: =DATEDIF(D3,DATE(2026,9,30),"Y") -> 37 | T3: =(IF(Q3="",DATE(2026,9,30),Q3)-E3)/365.25 -> 8.1040383 | U3: =_xlfn.XLOOKUP(Table1_1[[#This Row],[Bo''lim]],Bolimlar!A:A,Bolimlar!B:B,"Topilmadi") -> Jasur Yusupov | V3: =IF(P3="Ha",1,0) -> 0 | W3: =IF(T3<1,"1 yildan kam",IF(T3<3,"1-3 yil","3 yildan ko'p")) -> 3 yildan ko'p
A4: EMP-0269 | B4: Gulnora Karimova | C4: Ayol | D4: 31509 | E4: 45321 | F4: IT | G4: Tizim administratori | H4: Senior | I4: Toshkent | J4: 21250000 | K4: 4 | L4: 4 | M4: 1 | N4: Ofis | O4: O'rta maxsus | P4: Yo'q | S4: =DATEDIF(D4,DATE(2026,9,30),"Y") -> 40 | T4: =(IF(Q4="",DATE(2026,9,30),Q4)-E4)/365.25 -> 2.6666667 | U4: =_xlfn.XLOOKUP(Table1_1[[#This Row],[Bo''lim]],Bolimlar!A:A,Bolimlar!B:B,"Topilmadi") -> Jasur Yusupov | V4: =IF(P4="Ha",1,0) -> 0 | W4: =IF(T4<1,"1 yildan kam",IF(T4<3,"1-3 yil","3 yildan ko'p")) -> 1-3 yil
A5: EMP-0533 | B5: Jahongir Sobirov | C5: Erkak | D5: 33829 | E5: 43835 | F5: IT | G5: QA muhandisi | H5: Senior | I5: Buxoro | J5: 20780000 | K5: 3 | L5: 5 | M5: 0 | N5: Ofis | O5: O'rta maxsus | P5: Yo'q | S5: =DATEDIF(D5,DATE(2026,9,30),"Y") -> 34 | T5: =(IF(Q5="",DATE(2026,9,30),Q5)-E5)/365.25 -> 6.7351129 | U5: =_xlfn.XLOOKUP(Table1_1[[#This Row],[Bo''lim]],Bolimlar!A:A,Bolimlar!B:B,"Topilmadi") -> Jasur Yusupov | V5: =IF(P5="Ha",1,0) -> 0 | W5: =IF(T5<1,"1 yildan kam",IF(T5<3,"1-3 yil","3 yildan ko'p")) -> 3 yildan ko'p
A6: EMP-0486 | B6: Timur Saidov | C6: Erkak | D6: 32285 | E6: 45979 | F6: IT | G6: Tizim administratori | H6: Senior | I6: Qarshi | J6: 20380000 | K6: 2 | L6: 4 | M6: 10 | N6: Masofaviy | O6: Magistr | P6: Yo'q | S6: =DATEDIF(D6,DATE(2026,9,30),"Y") -> 38 | T6: =(IF(Q6="",DATE(2026,9,30),Q6)-E6)/365.25 -> 0.86516085 | U6: =_xlfn.XLOOKUP(Table1_1[[#This Row],[Bo''lim]],Bolimlar!A:A,Bolimlar!B:B,"Topilmadi") -> Jasur Yusupov | V6: =IF(P6="Ha",1,0) -> 0 | W6: =IF(T6<1,"1 yildan kam",IF(T6<3,"1-3 yil","3 yildan ko'p")) -> 1 yildan kam
A7: EMP-0226 | B7: Islom Mirzayev | C7: Erkak | D7: 36982 | E7: 45790 | F7: IT | G7: QA muhandisi | H7: Senior | I7: Toshkent | J7: 20230000 | K7: 1 | L7: 2 | M7: 22 | N7: Masofaviy | O7: O'rta maxsus | P7: Yo'q | S7: =DATEDIF(D7,DATE(2026,9,30),"Y") -> 25 | T7: =(IF(Q7="",DATE(2026,9,30),Q7)-E7)/365.25 -> 1.3826146 | U7: =_xlfn.XLOOKUP(Table1_1[[#This Row],[Bo''lim]],Bolimlar!A:A,Bolimlar!B:B,"Topilmadi") -> Jasur Yusupov | V7: =IF(P7="Ha",1,0) -> 0 | W7: =IF(T7<1,"1 yildan kam",IF(T7<3,"1-3 yil","3 yildan ko'p")) -> 1-3 yil
A8: EMP-0538 | B8: Bobur Yusupov | C8: Erkak | D8: 37680 | E8: 46064 | F8: IT | G8: Dasturchi | H8: Senior | I8: Toshkent | J8: 19350000 | K8: 4 | L8: 3 | M8: 21 | N8: Gibrid | O8: Bakalavr | P8: Yo'q | S8: =DATEDIF(D8,DATE(2026,9,30),"Y") -> 23 | T8: =(IF(Q8="",DATE(2026,9,30),Q8)-E8)/365.25 -> 0.63244353 | U8: =_xlfn.XLOOKUP(Table1_1[[#This Row],[Bo''lim]],Bolimlar!A:A,Bolimlar!B:B,"Topilmadi") -> Jasur Yusupov | V8: =IF(P8="Ha",1,0) -> 0 | W8: =IF(T8<1,"1 yildan kam",IF(T8<3,"1-3 yil","3 yildan ko'p")) -> 1 yildan kam
A9: EMP-0110 | B9: Doniyor Karimov | C9: Erkak | D9: 32634 | E9: 43714 | F9: IT | G9: Dasturchi | H9: Senior | I9: Toshkent | J9: 18800000 | K9: 2 | L9: 2 | M9: 0 | N9: Gibrid | O9: O'rta maxsus | P9: Yo'q | S9: =DATEDIF(D9,DATE(2026,9,30),"Y") -> 37 | T9: =(IF(Q9="",DATE(2026,9,30),Q9)-E9)/365.25 -> 7.0663929 | U9: =_xlfn.XLOOKUP(Table1_1[[#This Row],[Bo''lim]],Bolimlar!A:A,Bolimlar!B:B,"Topilmadi") -> Jasur Yusupov | V9: =IF(P9="Ha",1,0) -> 0 | W9: =IF(T9<1,"1 yildan kam",IF(T9<3,"1-3 yil","3 yildan ko'p")) -> 3 yildan ko'p
A10: EMP-0450 | B10: Islom Saidov | C10: Erkak | D10: 36137 | E10: 44829 | F10: IT | G10: Tizim administratori | H10: Senior | I10: Andijon | J10: 18530000 | K10: 3 | L10: 3 | M10: 25 | N10: Ofis | O10: Bakalavr | P10: Yo'q | S10: =DATEDIF(D10,DATE(2026,9,30),"Y") -> 27 | T10: =(IF(Q10="",DATE(2026,9,30),Q10)-E10)/365.25 -> 4.0136893 | U10: =_xlfn.XLOOKUP(Table1_1[[#This Row],[Bo''lim]],Bolimlar!A:A,Bolimlar!B:B,"Topilmadi") -> Jasur Yusupov | V10: =IF(P10="Ha",1,0) -> 0 | W10: =IF(T10<1,"1 yildan kam",IF(T10<3,"1-3 yil","3 yildan ko'p")) -> 3 yildan ko'p
A11: EMP-0317 | B11: Ulugbek Yusupov | C11: Erkak | D11: 38876 | E11: 46209 | F11: IT | G11: Dasturchi | H11: Senior | I11: Toshkent | J11: 18460000 | K11: 3 | L11: 3 | M11: 24 | N11: Ofis | O11: Magistr | P11: Yo'q | S11: =DATEDIF(D11,DATE(2026,9,30),"Y") -> 20 | T11: =(IF(Q11="",DATE(2026,9,30),Q11)-E11)/365.25 -> 0.23545517 | U11: =_xlfn.XLOOKUP(Table1_1[[#This Row],[Bo''lim]],Bolimlar!A:A,Bolimlar!B:B,"Topilmadi") -> Jasur Yusupov | V11: =IF(P11="Ha",1,0) -> 0 | W11: =IF(T11<1,"1 yildan kam",IF(T11<3,"1-3 yil","3 yildan ko'p")) -> 1 yildan kam
A12: EMP-0354 | B12: Sevara Mirzayeva | C12: Ayol | D12: 31451 | E12: 43389 | F12: IT | G12: Tizim administratori | H12: Senior | I12: Samarqand | J12: 17770000 | K12: 4 | L12: 5 | M12: 26 | N12: Ofis | O12: Bakalavr | P12: Yo'q | S12: =DATEDIF(D12,DATE(2026,9,30),"Y") -> 40 | T12: =(IF(Q12="",DATE(2026,9,30),Q12)-E12)/365.25 -> 7.9561944 | U12: =_xlfn.XLOOKUP(Table1_1[[#This Row],[Bo''lim]],Bolimlar!A:A,Bolimlar!B:B,"Topilmadi") -> Jasur Yusupov | V12: =IF(P12="Ha",1,0) -> 0 | W12: =IF(T12<1,"1 yildan kam",IF(T12<3,"1-3 yil","3 yildan ko'p")) -> 3 yildan ko'p
A13: EMP-0234 | B13: Rustam Tursunov | C13: Erkak | D13: 34312 | E13: 43508 | F13: IT | G13: Dasturchi | H13: Senior | I13: Toshkent | J13: 17680000 | K13: 4 | L13: 4 | M13: 0 | N13: Gibrid | O13: Bakalavr | P13: Yo'q | S13: =DATEDIF(D13,DATE(2026,9,30),"Y") -> 32 | T13: =(IF(Q13="",DATE(2026,9,30),Q13)-E13)/365.25 -> 7.6303901 | U13: =_xlfn.XLOOKUP(Table1_1[[#This Row],[Bo''lim]],Bolimlar!A:A,Bolimlar!B:B,"Topilmadi") -> Jasur Yusupov | V13: =IF(P13="Ha",1,0) -> 0 | W13: =IF(T13<1,"1 yildan kam",IF(T13<3,"1-3 yil","3 yildan ko'p")) -> 3 yildan ko'p
... A19: EMP-0701 | B19: Gulnora Saidova | C19: Ayol | D19: 37119 | E19: 46250 | F19: MARKETING | G19: Marketolog | H19: Senior | I19: Toshkent | J19: 16440000 | K19: 4 | L19: 3 | M19: 18 | N19: Ofis | O19: Bakalavr | P19: Yo'q | S19: =DATEDIF(D19,DATE(2026,9,30),"Y") -> 25 | T19: =(IF(Q19="",DATE(2026,9,30),Q19)-E19)/365.25 -> 0.12320329 | U19: =_xlfn.XLOOKUP(Table1_1[[#This Row],[Bo''lim]],Bolimlar!A:A,Bolimlar!B:B,"Topilmadi") -> Dilnoza Rahimova | V19: =IF(P19="Ha",1,0) -> 0 | W19: =IF(T19<1,"1 yildan kam",IF(T19<3,"1-3 yil","3 yildan ko'p")) -> 1 yildan kam
A20: EMP-0033 | B20: Shaxzod Nazarov | C20: Erkak | D20: 35217 | E20: 43567 | F20: MARKETING | G20: SMM mutaxassisi | H20: Senior | I20: Toshkent | J20: 16340000 | K20: 4 | L20: 5 | M20: 15 | N20: Ofis | P20: Yo'q | S20: =DATEDIF(D20,DATE(2026,9,30),"Y") -> 30 | T20: =(IF(Q20="",DATE(2026,9,30),Q20)-E20)/365.25 -> 7.4688569 | U20: =_xlfn.XLOOKUP(Table1_1[[#This Row],[Bo''lim]],Bolimlar!A:A,Bolimlar!B:B,"Topilmadi") -> Dilnoza Rahimova | V20: =IF(P20="Ha",1,0) -> 0 | W20: =IF(T20<1,"1 yildan kam",IF(T20<3,"1-3 yil","3 yildan ko'p")) -> 3 yildan ko'p
A21: EMP-0487 | B21: Sevara Nazarova | C21: Ayol | D21: 33567 | E21: 45053 | F21: SOTUV | G21: Savdo vakili | H21: Senior | I21: Toshkent | J21: 15750000 | K21: 3 | L21: 2 | M21: 9 | N21: Gibrid | O21: Magistr | P21: Yo'q | S21: =DATEDIF(D21,DATE(2026,9,30),"Y") -> 34 | T21: =(IF(Q21="",DATE(2026,9,30),Q21)-E21)/365.25 -> 3.4004107 | U21: =_xlfn.XLOOKUP(Table1_1[[#This Row],[Bo''lim]],Bolimlar!A:A,Bolimlar!B:B,"Topilmadi") -> Aziz Karimov | V21: =IF(P21="Ha",1,0) -> 0 | W21: =IF(T21<1,"1 yildan kam",IF(T21<3,"1-3 yil","3 yildan ko'p")) -> 3 yildan ko'p
A22: EMP-0770 | B22: Dilfuza Mirzayeva | C22: Ayol | D22: 35414 | E22: 46191 | F22: SOTUV | G22: Sotuv menejeri | H22: Senior | I22: Samarqand | J22: 15700000 | K22: 4 | L22: 3 | M22: 4 | N22: Ofis | O22: Bakalavr | P22: Yo'q | S22: =DATEDIF(D22,DATE(2026,9,30),"Y") -> 29 | T22: =(IF(Q22="",DATE(2026,9,30),Q22)-E22)/365.25 -> 0.28473648 | U22: =_xlfn.XLOOKUP(Table1_1[[#This Row],[Bo''lim]],Bolimlar!A:A,Bolimlar!B:B,"Topilmadi") -> Aziz Karimov | V22: =IF(P22="Ha",1,0) -> 0 | W22: =IF(T22<1,"1 yildan kam",IF(T22<3,"1-3 yil","3 yildan ko'p")) -> 1 yildan kam
A23: EMP-0047 | B23: Sherzod Ergashev | C23: Erkak | D23: 34829 | E23: 45275 | F23: SOTUV | G23: Hudud menejeri | H23: Senior | I23: Andijon | J23: 15660000 | K23: 1 | L23: 2 | M23: 10 | N23: Gibrid | O23: Bakalavr | P23: Yo'q | S23: =DATEDIF(D23,DATE(2026,9,30),"Y") -> 31 | T23: =(IF(Q23="",DATE(2026,9,30),Q23)-E23)/365.25 -> 2.7926078 | U23: =_xlfn.XLOOKUP(Table1_1[[#This Row],[Bo''lim]],Bolimlar!A:A,Bolimlar!B:B,"Topilmadi") -> Aziz Karimov | V23: =IF(P23="Ha",1,0) -> 0 | W23: =IF(T23<1,"1 yildan kam",IF(T23<3,"1-3 yil","3 yildan ko'p")) -> 1-3 yil
A24: EMP-0219 | B24: Kamola Tursunova | C24: Ayol | D24: 31485 | E24: 45195 | F24: IT | G24: QA muhandisi | H24: Senior | I24: Toshkent | J24: 15600000 | L24: 2 | M24: 16 | N24: Ofis | O24: Magistr | P24: Yo'q | S24: =DATEDIF(D24,DATE(2026,9,30),"Y") -> 40 | T24: =(IF(Q24="",DATE(2026,9,30),Q24)-E24)/365.25 -> 3.0116359 | U24: =_xlfn.XLOOKUP(Table1_1[[#This Row],[Bo''lim]],Bolimlar!A:A,Bolimlar!B:B,"Topilmadi") -> Jasur Yusupov | V24: =IF(P24="Ha",1,0) -> 0 | W24: =IF(T24<1,"1 yildan kam",IF(T24<3,"1-3 yil","3 yildan ko'p")) -> 3 yildan ko'p
A25: EMP-0452 | B25: Malika Sobirova | C25: Ayol | D25: 31031 | E25: 45312 | F25: MOLIYA | G25: Moliyaviy tahlilchi | H25: Senior | I25: Toshkent | J25: 15460000 | K25: 3 | L25: 3 | M25: 24 | N25: Ofis | O25: Bakalavr | P25: Yo'q | S25: =DATEDIF(D25,DATE(2026,9,30),"Y") -> 41 | T25: =(IF(Q25="",DATE(2026,9,30),Q25)-E25)/365.25 -> 2.6913073 | U25: =_xlfn.XLOOKUP(Table1_1[[#This Row],[Bo''lim]],Bolimlar!A:A,Bolimlar!B:B,"Topilmadi") -> Madina Abdullayeva | V25: =IF(P25="Ha",1,0) -> 0 | W25: =IF(T25<1,"1 yildan kam",IF(T25<3,"1-3 yil","3 yildan ko'p")) -> 1-3 yil
A26: EMP-0215 | B26: Dilnoza Ergasheva | C26: Ayol | D26: 28681 | E26: 44405 | F26: SOTUV | G26: Hudud menejeri | H26: Senior | I26: Toshkent | J26: 15380000 | K26: 4 | L26: 4 | M26: 16 | N26: Gibrid | O26: O'rta maxsus | P26: Yo'q | S26: =DATEDIF(D26,DATE(2026,9,30),"Y") -> 48 | T26: =(IF(Q26="",DATE(2026,9,30),Q26)-E26)/365.25 -> 5.174538 | U26: =_xlfn.XLOOKUP(Table1_1[[#This Row],[Bo''lim]],Bolimlar!A:A,Bolimlar!B:B,"Topilmadi") -> Aziz Karimov | V26: =IF(P26="Ha",1,0) -> 0 | W26: =IF(T26<1,"1 yildan kam",IF(T26<3,"1-3 yil","3 yildan ko'p")) -> 3 yildan ko'p
A27: EMP-0190 | B27: Shaxzod Abdullayev | C27: Erkak | D27: 35299 | E27: 43693 | F27: IT | G27: Dasturchi | H27: Senior | I27: Andijon | J27: 15350000 | K27: 3 | L27: 4 | M27: 5 | N27: Masofaviy | O27: Bakalavr | P27: Yo'q | S27: =DATEDIF(D27,DATE(2026,9,30),"Y") -> 30 | T27: =(IF(Q27="",DATE(2026,9,30),Q27)-E27)/365.25 -> 7.1238877 | U27: =_xlfn.XLOOKUP(Table1_1[[#This Row],[Bo''lim]],Bolimlar!A:A,Bolimlar!B:B,"Topilmadi") -> Jasur Yusupov | V27: =IF(P27="Ha",1,0) -> 0 | W27: =IF(T27<1,"1 yildan kam",IF(T27<3,"1-3 yil","3 yildan ko'p")) -> 3 yildan ko'p
A28: EMP-0397 | B28: Ulugbek Saidov | C28: Erkak | D28: 34017 | E28: 46059 | F28: MARKETING | G28: SMM mutaxassisi | H28: Senior | I28: Toshkent | J28: 15320000 | K28: 3 | L28: 4 | M28: 21 | N28: Gibrid | O28: O'rta maxsus | P28: Yo'q | S28: =DATEDIF(D28,DATE(2026,9,30),"Y") -> 33 | T28: =(IF(Q28="",DATE(2026,9,30),Q28)-E28)/365.25 -> 0.64613279 | U28: =_xlfn.XLOOKUP(Table1_1[[#This Row],[Bo''lim]],Bolimlar!A:A,Bolimlar!B:B,"Topilmadi") -> Dilnoza Rahimova | V28: =IF(P28="Ha",1,0) -> 0 | W28: =IF(T28<1,"1 yildan kam",IF(T28<3,"1-3 yil","3 yildan ko'p")) -> 1 yildan kam
A29: EMP-0094 | B29: Sevara Ergasheva | C29: Ayol | D29: 31799 | E29: 45323 | F29: IT | G29: QA muhandisi | H29: Senior | I29: Namangan | J29: 15300000 | K29: 4 | L29: 3 | M29: 6 | N29: Ofis | O29: Bakalavr | P29: Yo'q | S29: =DATEDIF(D29,DATE(2026,9,30),"Y") -> 39 | T29: =(IF(Q29="",DATE(2026,9,30),Q29)-E29)/365.25 -> 2.661191 | U29: =_xlfn.XLOOKUP(Table1_1[[#This Row],[Bo''lim]],Bolimlar!A:A,Bolimlar!B:B,"Topilmadi") -> Jasur Yusupov | V29: =IF(P29="Ha",1,0) -> 0 | W29: =IF(T29<1,"1 yildan kam",IF(T29<3,"1-3 yil","3 yildan ko'p")) -> 1-3 yil
A30: EMP-0342 | B30: Nigora Qodirova | C30: Ayol | D30: 33566 | E30: 45823 | F30: SOTUV | G30: Hudud menejeri | H30: Senior | I30: Qarshi | J30: 15280000 | K30: 3 | L30: 4 | M30: 19 | N30: Ofis | O30: Magistr | P30: Yo'q | S30: =DATEDIF(D30,DATE(2026,9,30),"Y") -> 34 | T30: =(IF(Q30="",DATE(2026,9,30),Q30)-E30)/365.25 -> 1.2922656 | U30: =_xlfn.XLOOKUP(Table1_1[[#This Row],[Bo''lim]],Bolimlar!A:A,Bolimlar!B:B,"Topilmadi") -> Aziz Karimov | V30: =IF(P30="Ha",1,0) -> 0 | W30: =IF(T30<1,"1 yildan kam",IF(T30<3,"1-3 yil","3 yildan ko'p")) -> 1-3 yil
A31: EMP-0480 | B31: Otabek Tursunov | C31: Erkak | D31: 30901 | E31: 44326 | F31: SOTUV | G31: Savdo vakili | H31: Senior | I31: Andijon | J31: 15280000 | K31: 4 | L31: 3 | M31: 11 | N31: Gibrid | O31: Bakalavr | P31: Yo'q | S31: =DATEDIF(D31,DATE(2026,9,30),"Y") -> 42 | T31: =(IF(Q31="",DATE(2026,9,30),Q31)-E31)/365.25 -> 5.3908282 | U31: =_xlfn.XLOOKUP(Table1_1[[#This Row],[Bo''lim]],Bolimlar!A:A,Bolimlar!B:B,"Topilmadi") -> Aziz Karimov | V31: =IF(P31="Ha",1,0) -> 0 | W31: =IF(T31<1,"1 yildan kam",IF(T31<3,"1-3 yil","3 yildan ko'p")) -> 3 yildan ko'p
A32: EMP-0160 | B32: Zilola Karimova | C32: Ayol | D32: 35294 | E32: 46257 | F32: IT | G32: Dasturchi | H32: Senior | I32: Toshkent | J32: 15270000 | K32: 3 | L32: 5 | M32: 0 | N32: Gibrid | P32: Yo'q | S32: =DATEDIF(D32,DATE(2026,9,30),"Y") -> 30 | T32: =(IF(Q32="",DATE(2026,9,30),Q32)-E32)/365.25 -> 0.10403833 | U32: =_xlfn.XLOOKUP(Table1_1[[#This Row],[Bo''lim]],Bolimlar!A:A,Bolimlar!B:B,"Topilmadi") -> Jasur Yusupov | V32: =IF(P32="Ha",1,0) -> 0 | W32: =IF(T32<1,"1 yildan kam",IF(T32<3,"1-3 yil","3 yildan ko'p")) -> 1 yildan kam
A33: EMP-0199 | B33: Ulugbek Ergashev | C33: Erkak | D33: 25782 | E33: 45593 | F33: MOLIYA | G33: Moliyaviy tahlilchi | H33: Senior | I33: Toshkent | J33: 15200000 | K33: 3 | L33: 4 | M33: 6 | N33: Gibrid | O33: Bakalavr | P33: Yo'q | S33: =DATEDIF(D33,DATE(2026,9,30),"Y") -> 56 | T33: =(IF(Q33="",DATE(2026,9,30),Q33)-E33)/365.25 -> 1.9219713 | U33: =_xlfn.XLOOKUP(Table1_1[[#This Row],[Bo''lim]],Bolimlar!A:A,Bolimlar!B:B,"Topilmadi") -> Madina Abdullayeva | V33: =IF(P33="Ha",1,0) -> 0 | W33: =IF(T33<1,"1 yildan kam",IF(T33<3,"1-3 yil","3 yildan ko'p")) -> 1-3 yil
A34: EMP-0613 | B34: Jasur Umarov | C34: Erkak | D34: 32934 | E34: 45499 | F34: SOTUV | G34: Hudud menejeri | H34: Senior | I34: Andijon | J34: 15150000 | K34: 5 | L34: 4 | M34: 20 | N34: Ofis | O34: Bakalavr | P34: Yo'q | S34: =DATEDIF(D34,DATE(2026,9,30),"Y") -> 36 | T34: =(IF(Q34="",DATE(2026,9,30),Q34)-E34)/365.25 -> 2.1793292 | U34: =_xlfn.XLOOKUP(Table1_1[[#This Row],[Bo''lim]],Bolimlar!A:A,Bolimlar!B:B,"Topilmadi") -> Aziz Karimov | V34: =IF(P34="Ha",1,0) -> 0 | W34: =IF(T34<1,"1 yildan kam",IF(T34<3,"1-3 yil","3 yildan ko'p")) -> 1-3 yil
A35: EMP-0540 | B35: Kamola Abdullayeva | C35: Ayol | D35: 34075 | E35: 46152 | F35: SOTUV | G35: Savdo vakili | H35: Senior | I35: Buxoro | J35: 15080000 | K35: 5 | L35: 3 | M35: 33 | N35: Gibrid | O35: Bakalavr | P35: Yo'q | S35: =DATEDIF(D35,DATE(2026,9,30),"Y") -> 33 | T35: =(IF(Q35="",DATE(2026,9,30),Q35)-E35)/365.25 -> 0.39151266 | U35: =_xlfn.XLOOKUP(Table1_1[[#This Row],[Bo''lim]],Bolimlar!A:A,Bolimlar!B:B,"Topilmadi") -> Aziz Karimov | V35: =IF(P35="Ha",1,0) -> 0 | W35: =IF(T35<1,"1 yildan kam",IF(T35<3,"1-3 yil","3 yildan ko'p")) -> 1 yildan kam
A36: EMP-0455 | B36: Malika Rahimova | C36: Ayol | D36: 35667 | E36: 45991 | F36: MARKETING | G36: SMM mutaxassisi | H36: Senior | I36: Toshkent | J36: 15040000 | K36: 4 | L36: 2 | M36: 10 | N36: Gibrid | O36: Magistr | P36: Yo'q | S36: =DATEDIF(D36,DATE(2026,9,30),"Y") -> 29 | T36: =(IF(Q36="",DATE(2026,9,30),Q36)-E36)/365.25 -> 0.83230664 | U36: =_xlfn.XLOOKUP(Table1_1[[#This Row],[Bo''lim]],Bolimlar!A:A,Bolimlar!B:B,"Topilmadi") -> Dilnoza Rahimova | V36: =IF(P36="Ha",1,0) -> 0 | W36: =IF(T36<1,"1 yildan kam",IF(T36<3,"1-3 yil","3 yildan ko'p")) -> 1 yildan kam
A37: EMP-0653 | B37: Madina Abdullayeva | C37: Ayol | D37: 34503 | E37: 45514 | F37: MARKETING | G37: Kontent menejer | H37: Senior | I37: Buxoro | J37: 15030000 | K37: 3 | L37: 3 | M37: 38 | N37: Ofis | O37: Bakalavr | P37: Yo'q | S37: =DATEDIF(D37,DATE(2026,9,30),"Y") -> 32 | T37: =(IF(Q37="",DATE(2026,9,30),Q37)-E37)/365.25 -> 2.1382615 | U37: =_xlfn.XLOOKUP(Table1_1[[#This Row],[Bo''lim]],Bolimlar!A:A,Bolimlar!B:B,"Topilmadi") -> Dilnoza Rahimova | V37: =IF(P37="Ha",1,0) -> 0 | W37: =IF(T37<1,"1 yildan kam",IF(T37<3,"1-3 yil","3 yildan ko'p")) -> 1-3 yil
A38: EMP-0249 | B38: Sevara Ismoilova | C38: Ayol | D38: 32649 | E38: 43892 | F38: SOTUV | G38: Savdo vakili | H38: Senior | I38: Farg'ona | J38: 14930000 | K38: 4 | L38: 1 | M38: 35 | N38: Ofis | O38: O'rta maxsus | P38: Yo'q | S38: =DATEDIF(D38,DATE(2026,9,30),"Y") -> 37 | T38: =(IF(Q38="",DATE(2026,9,30),Q38)-E38)/365.25 -> 6.5790554 | U38: =_xlfn.XLOOKUP(Table1_1[[#This Row],[Bo''lim]],Bolimlar!A:A,Bolimlar!B:B,"Topilmadi") -> Aziz Karimov | V38: =IF(P38="Ha",1,0) -> 0 | W38: =IF(T38<1,"1 yildan kam",IF(T38<3,"1-3 yil","3 yildan ko'p")) -> 3 yildan ko'p
A39: EMP-0595 | B39: Aziza Tursunova | C39: Ayol | D39: 36970 | E39: 45454 | F39: MOLIYA | G39: Kassir | H39: Senior | I39: Samarqand | J39: 14850000 | K39: 5 | L39: 3 | M39: 8 | N39: Gibrid | O39: Bakalavr | P39: Yo'q | S39: =DATEDIF(D39,DATE(2026,9,30),"Y") -> 25 | T39: =(IF(Q39="",DATE(2026,9,30),Q39)-E39)/365.25 -> 2.3025325 | U39: =_xlfn.XLOOKUP(Table1_1[[#This Row],[Bo''lim]],Bolimlar!A:A,Bolimlar!B:B,"Topilmadi") -> Madina Abdullayeva | V39: =IF(P39="Ha",1,0) -> 0 | W39: =IF(T39<1,"1 yildan kam",IF(T39<3,"1-3 yil","3 yildan ko'p")) -> 1-3 yil
A40: EMP-0787 | B40: Gulnora Rahimova | C40: Ayol | D40: 37018 | E40: 45558 | F40: SOTUV | G40: Sotuv menejeri | H40: Senior | I40: Toshkent | J40: 14850000 | K40: 4 | L40: 3 | M40: 25 | N40: Ofis | O40: Bakalavr | P40: Yo'q | S40: =DATEDIF(D40,DATE(2026,9,30),"Y") -> 25 | T40: =(IF(Q40="",DATE(2026,9,30),Q40)-E40)/365.25 -> 2.017796 | U40: =_xlfn.XLOOKUP(Table1_1[[#This Row],[Bo''lim]],Bolimlar!A:A,Bolimlar!B:B,"Topilmadi") -> Aziz Karimov | V40: =IF(P40="Ha",1,0) -> 0 | W40: =IF(T40<1,"1 yildan kam",IF(T40<3,"1-3 yil","3 yildan ko'p")) -> 1-3 yil
A41: EMP-0244 | B41: Akmal Qodirov | C41: Erkak | D41: 29365 | E41: 44470 | F41: MARKETING | G41: Marketolog | H41: Senior | I41: Samarqand | J41: 14780000 | K41: 1 | L41: 5 | M41: 9 | N41: Ofis | O41: Magistr | P41: Yo'q | S41: =DATEDIF(D41,DATE(2026,9,30),"Y") -> 46 | T41: =(IF(Q41="",DATE(2026,9,30),Q41)-E41)/365.25 -> 4.9965777 | U41: =_xlfn.XLOOKUP(Table1_1[[#This Row],[Bo''lim]],Bolimlar!A:A,Bolimlar!B:B,"Topilmadi") -> Dilnoza Rahimova | V41: =IF(P41="Ha",1,0) -> 0 | W41: =IF(T41<1,"1 yildan kam",IF(T41<3,"1-3 yil","3 yildan ko'p")) -> 3 yildan ko'p
A42: EMP-0001 | B42: Nodira Ismoilova | C42: Ayol | D42: 34946 | E42: 43842 | F42: IT | G42: Dasturchi | H42: Senior | I42: Toshkent | J42: 14720000 | K42: 3 | L42: 2 | M42: 8 | N42: Gibrid | O42: Bakalavr | P42: Ha | Q42: 46237 | R42: Maosh past | S42: =DATEDIF(D42,DATE(2026,9,30),"Y") -> 31 | T42: =(IF(Q42="",DATE(2026,9,30),Q42)-E42)/365.25 -> 6.5571526 | U42: =_xlfn.XLOOKUP(Table1_1[[#This Row],[Bo''lim]],Bolimlar!A:A,Bolimlar!B:B,"Topilmadi") -> Jasur Yusupov | V42: =IF(P42="Ha",1,0) -> 1 | W42: =IF(T42<1,"1 yildan kam",IF(T42<3,"1-3 yil","3 yildan ko'p")) -> 3 yildan ko'p
A43: EMP-0742 | B43: Otabek Mirzayev | C43: Erkak | D43: 34255 | E43: 46101 | F43: HR | G43: Rekruter | H43: Senior | I43: Samarqand | J43: 14600000 | K43: 1 | L43: 4 | M43: 12 | N43: Masofaviy | O43: Bakalavr | P43: Yo'q | S43: =DATEDIF(D43,DATE(2026,9,30),"Y") -> 32 | T43: =(IF(Q43="",DATE(2026,9,30),Q43)-E43)/365.25 -> 0.53114305 | U43: =_xlfn.XLOOKUP(Table1_1[[#This Row],[Bo''lim]],Bolimlar!A:A,Bolimlar!B:B,"Topilmadi") -> Nodira Tursunova | V43: =IF(P43="Ha",1,0) -> 0 | W43: =IF(T43<1,"1 yildan kam",IF(T43<3,"1-3 yil","3 yildan ko'p")) -> 1 yildan kam
A44: EMP-0366 | B44: Jasur Ergashev | C44: Erkak | D44: 31019 | E44: 44081 | F44: IT | G44: QA muhandisi | H44: Senior | I44: Farg'ona | J44: 14560000 | K44: 4 | L44: 4 | M44: 17 | N44: Ofis | O44: Bakalavr | P44: Ha | Q44: 46156 | R44: Maosh past | S44: =DATEDIF(D44,DATE(2026,9,30),"Y") -> 41 | T44: =(IF(Q44="",DATE(2026,9,30),Q44)-E44)/365.25 -> 5.6810404 | U44: =_xlfn.XLOOKUP(Table1_1[[#This Row],[Bo''lim]],Bolimlar!A:A,Bolimlar!B:B,"Topilmadi") -> Jasur Yusupov | V44: =IF(P44="Ha",1,0) -> 1 | W44: =IF(T44<1,"1 yildan kam",IF(T44<3,"1-3 yil","3 yildan ko'p")) -> 3 yildan ko'p
A45: EMP-0367 | B45: Zilola Qodirova | C45: Ayol | D45: 32361 | E45: 46006 | F45: SOTUV | G45: Savdo vakili | H45: Senior | I45: Buxoro | J45: 14550000 | K45: 2 | L45: 4 | M45: 17 | N45: Gibrid | P45: Ha | Q45: 46143 | R45: Boshqa shaharga ko'chdi | S45: =DATEDIF(D45,DATE(2026,9,30),"Y") -> 38 | T45: =(IF(Q45="",DATE(2026,9,30),Q45)-E45)/365.25 -> 0.37508556 | U45: =_xlfn.XLOOKUP(Table1_1[[#This Row],[Bo''lim]],Bolimlar!A:A,Bolimlar!B:B,"Topilmadi") -> Aziz Karimov | V45: =IF(P45="Ha",1,0) -> 1 | W45: =IF(T45<1,"1 yildan kam",IF(T45<3,"1-3 yil","3 yildan ko'p")) -> 1 yildan kam
...

Sheet HR_Raw
A1: Xodim_ID | B1: Ism_familiya | C1: Jins | D1: Tug'ilgan_sana | E1: Ishga_kirgan_sana | F1: Bo'lim | G1: Lavozim | H1: Daraja | I1: Shahar | J1: Oylik (so'm) | K1: Samaradorlik_bahosi (1-5) | L1: Mamnunlik_bahosi (1-5) | M1: Qo'shimcha_ish_soati (oyiga) | N1: Ish_formati | O1: Ta'lim | P1: Ishdan_ketgan | Q1: Ketgan_sana | R1: Ketish_sababi
A2: EMP-0001 | B2: Nodira Ismoilova | C2: Ayol | D2: 34946 | E2: 43842 | F2: IT | G2: Dasturchi | H2: Senior | I2: Toshkent | J2: 14720000 | K2: 3 | L2: 2 | M2: 8 | N2: Gibrid | O2: Bakalavr | P2: Ha | Q2: 46237 | R2: Maosh past
A3: EMP-0002 | B3: Timur Karimov | C3: Erkak | D3: 33307 | E3: 44108 | F3: IT | G3: QA muhandisi | H3: Junior | I3: Samarqand | J3: 6490000 | K3: 3 | L3: 4 | M3: 11 | N3: Gibrid | O3: O'rta maxsus | P3: Yo'q
A4: EMP-0003 | B4: Rustam Qodirov | C4: Erkak | D4: 35596 | E4: 44356 | F4: HR | G4: Rekruter | H4: Junior | I4: Toshkent | J4: 3190000 | K4: 4 | L4: 2 | M4: 2 | N4: Ofis | O4: Bakalavr | P4: Yo'q
A5: EMP-0004 | B5: Bobur Saidov | C5: Erkak | D5: 38062 | E5: 45998 | F5: IT | G5: QA muhandisi | H5: Junior | I5: Farg'ona | J5: 6410000 | K5: 4 | L5: 3 | M5: 20 | N5: Ofis | O5: O'rta maxsus | P5: Yo'q
A6: EMP-0005 | B6: Sherzod Qodirov | C6: Erkak | D6: 34691 | E6: 45792 | F6: Marketing | G6: Kontent menejer | H6: Senior | I6: Toshkent | J6: 12290000 | K6: 3 | L6: 4 | M6: 8 | N6: Ofis | O6: O'rta maxsus | P6: Yo'q
A7: EMP-0006 | B7: Rustam Normatov | C7: Erkak | D7: 35259 | E7: 44851 | F7: Mijozlar xizmati | G7: Mijozlar bilan ishlash mutaxassisi | H7: Junior | I7: Toshkent | J7: 3280000 | K7: 5 | L7: 4 | M7: 35 | N7: Ofis | O7: Magistr | P7: Yo'q
A8: EMP-0007 | B8: Otabek Rahimov | C8: Erkak | D8: 33329 | E8: 43997 | F8: Moliya | G8: Kassir | H8: Junior | I8: Farg'ona | J8: 3620000 | K8: 3 | L8: 4 | M8: 18 | N8: Ofis | O8: Magistr | P8: Yo'q
A9: EMP-0008 | B9: Doniyor Umarov | C9: Erkak | D9: 30281 | E9: 43097 | F9: Moliya | G9: Moliyaviy tahlilchi | H9: Junior | I9: Toshkent | J9: 4700000 | K9: 2 | L9: 1 | M9: 0 | N9: Ofis | O9: Bakalavr | P9: Ha | Q9: 46006 | R9: Rahbar bilan muammo
A10: EMP-0009 | B10: Behruz Mirzayev | C10: Erkak | D10: 29141 | E10: 45147 | F10: Sotuv | G10: Savdo vakili | H10: Senior | I10: Toshkent | J10: 12840000 | L10: 3 | M10: 22 | N10: Ofis | O10: Bakalavr | P10: Yo'q
A11: EMP-0010 | B11: Feruza Sobirova | C11: Ayol | D11: 35537 | E11: 43229 | F11: IT | G11: QA muhandisi | H11: Middle | I11: Toshkent | J11: 10290000 | K11: 5 | L11: 5 | M11: 0 | N11: Gibrid | O11: O'rta maxsus | P11: Yo'q
A12: EMP-0011 | B12: Ulugbek Hasanov | C12: Erkak | D12: 33354 | E12: 43753 | F12: Sotuv | G12: Savdo vakili | H12: Middle | I12: Toshkent | J12: 7310000 | K12: 3 | L12: 1 | M12: 30 | N12: Gibrid | O12: Bakalavr | P12: Yo'q
A13: EMP-0012 | B13: Feruza Normatova | C13: Ayol | D13: 27183 | E13: 44226 | F13: Sotuv | G13: Sotuv menejeri | H13: Middle | I13: Farg'ona | J13: 7190000 | K13: 5 | L13: 4 | M13: 0 | N13: Ofis | O13: O'rta maxsus | P13: Yo'q
A14: EMP-0013 | B14: Timur Normatov | C14: Erkak | D14: 34772 | E14: 46128 | F14: Mijozlar xizmati | G14: Mijozlar bilan ishlash mutaxassisi | H14: Junior | I14: Samarqand | J14: 3550000 | K14: 3 | L14: 4 | M14: 6 | N14: Gibrid | O14: Bakalavr | P14: Ha | Q14: 46204 | R14: Maosh past
A15: EMP-0014 | B15: Islom Hasanov | C15: Erkak | D15: 33121 | E15: 44904 | F15: sotuv | G15: Hudud menejeri | H15: Middle | I15: Samarqand | J15: 8770000 | K15: 3 | L15: 5 | M15: 12 | N15: Ofis | O15: Bakalavr | P15: Yo'q
A16: EMP-0015 | B16: Malika Saidova | C16: Ayol | D16: 35776 | E16: 46025 | F16: Mijozlar xizmati | G16: Mijozlar bilan ishlash mutaxassisi | H16: Senior | I16: Andijon | J16: 8630000 | K16: 2 | L16: 3 | M16: 21 | N16: Gibrid | O16: O'rta maxsus | P16: Yo'q
A17: EMP-0016 | B17: Islom Mirzayev | C17: Erkak | D17: 34872 | E17: 45688 | F17: Moliya | G17: Kassir | H17: Middle | I17: Andijon | J17: 9450000 | K17: 2 | L17: 2 | M17: 0 | N17: Ofis | O17: Magistr | P17: Ha | Q17: 46211 | R17: Rahbar bilan muammo
A18: EMP-0017 | B18: Zilola Mirzayeva | C18: Ayol | D18: 30795 | E18: 44740 | F18: Marketing | G18: Kontent menejer | H18: Middle | I18: Samarqand | J18: 9240000 | K18: 4 | L18: 5 | M18: 9 | N18: Masofaviy | O18: Magistr | P18: Yo'q
A19: EMP-0018 | B19: Nodira Ismoilova | C19: Ayol | D19: 32195 | E19: 44085 | F19: Marketing | G19: Marketolog | H19: Junior | I19: Toshkent | J19: 3410000 | K19: 4 | L19: 5 | M19: 19 | N19: Gibrid | O19: O'rta maxsus | P19: Yo'q
A20: EMP-0019 | B20: Shahlo Ergasheva | C20: Ayol | D20: 31995 | E20: 44577 | F20: Mijozlar xizmati | G20: Call-markaz operatori | H20: Junior | I20: Toshkent | J20: 3220000 | K20: 3 | L20: 2 | M20: 14 | N20: Ofis | O20: O'rta maxsus | P20: Ha | Q20: 46004 | R20: Rahbar bilan muammo
A21: EMP-0020 | B21: Nigora Mirzayeva | C21: Ayol | D21: 36217 | E21: 44775 | F21: Sotuv | G21: Sotuv menejeri | H21: Junior | I21: Namangan | J21: 4810000 | K21: 3 | L21: 4 | M21: 42 | N21: Gibrid | O21: Bakalavr | P21: Yo'q
A22: EMP-0021 | B22: Mohira Nazarova | C22: Ayol | D22: 33578 | E22: 42372 | F22: IT | G22: Dasturchi | H22: Junior | I22: Toshkent | J22: 4450000 | K22: 3 | L22: 4 | M22: 13 | N22: Ofis | O22: O'rta maxsus | P22: Yo'q
A23: EMP-0022 | B23: Malika Mirzayeva | C23: Ayol | D23: 32237 | E23: 43635 | F23: Mijozlar xizmati | G23: Mijozlar bilan ishlash mutaxassisi | H23: Junior | I23: Toshkent | J23: 2900000 | K23: 3 | L23: 4 | M23: 24 | N23: Ofis | O23: Bakalavr | P23: Yo'q
A24: EMP-0023 | B24: Dilnoza Karimova | C24: Ayol | D24: 31154 | E24: 45783 | F24: IT | G24: Tizim administratori | H24: Junior | I24: Buxoro | J24: 5410000 | K24: 3 | L24: 4 | M24: 13 | N24: Ofis | O24: Magistr | P24: Yo'q
A25: EMP-0024 | B25: Shahlo Sobirova | C25: Ayol | D25: 31119 | E25: 42337 | F25: Mijozlar xizmati | G25: Call-markaz operatori | H25: Senior | I25: Namangan | J25: 11000000 | K25: 5 | L25: 3 | M25: 1 | N25: Ofis | O25: Bakalavr | P25: Yo'q
A26: EMP-0025 | B26: Sevara Abdullayeva | C26: Ayol | D26: 34399 | E26: 46166 | F26: Marketing | G26: Marketolog | H26: Junior | I26: Toshkent | J26: 5190000 | K26: 4 | L26: 2 | M26: 9 | N26: Masofaviy | O26: O'rta maxsus | P26: Yo'q
A27: EMP-0026 | B27: Madina Qodirova | C27: Ayol | D27: 34806 | E27: 43085 | F27: Mijozlar xizmati | G27: Call-markaz operatori | H27: Junior | I27: Toshkent | J27: 3040000 | K27: 2 | L27: 1 | M27: 30 | N27: Gibrid | O27: Magistr | P27: Ha | Q27: 46199 | R27: Ish yuklamasi ko'p
A28: EMP-0027 | B28: Dilfuza Nazarova | C28: Ayol | D28: 34843 | E28: 45843 | F28: Logistika | G28: Logist | H28: Junior | I28: Samarqand | J28: 4310000 | K28: 4 | L28: 4 | M28: 8 | N28: Ofis | O28: Bakalavr | P28: Yo'q
A29: EMP-0028 | B29: Jahongir Rahimov | C29: Erkak | D29: 33028 | E29: 45226 | F29: IT | G29: Tizim administratori | H29: Middle | I29: Andijon | J29: 10770000 | K29: 4 | L29: 3 | M29: 13 | N29: Ofis | O29: Bakalavr | P29: Yo'q
A30: EMP-0029 | B30: Sardor Ergashev | C30: Erkak | D30: 34393 | E30: 43772 | F30: Marketing | G30: Kontent menejer | H30: Middle | I30: Toshkent | J30: 8160000 | K30: 3 | L30: 4 | M30: 4 | N30: Ofis | O30: O'rta maxsus | P30: Yo'q
A31: EMP-0030 | B31: Sardor Mirzayev | C31: Erkak | D31: 33230 | E31: 44755 | F31: Marketing | G31: Kontent menejer | H31: Junior | I31: Andijon | J31: 4170000 | K31: 5 | L31: 2 | M31: 18 | N31: Ofis | O31: Bakalavr | P31: Yo'q
A32: EMP-0031 | B32: Feruza Normatova | C32: Ayol | D32: 30416 | E32: 44674 | F32: Mijozlar xizmati | G32: Mijozlar bilan ishlash mutaxassisi | H32: Junior | I32: Namangan | J32: 3710000 | K32: 5 | L32: 3 | M32: 30 | N32: Ofis | O32: O'rta maxsus | P32: Yo'q
A33: EMP-0032 | B33: Otabek Ergashev | C33: Erkak | D33: 38796 | E33: 46232 | F33: Mijozlar xizmati | G33: Mijozlar bilan ishlash mutaxassisi | H33: Senior | I33: Buxoro | J33: 9110000 | K33: 5 | L33: 3 | M33: 8 | N33: Ofis | O33: Bakalavr | P33: Yo'q
A34: EMP-0033 | B34: Shaxzod Nazarov | C34: Erkak | D34: 35217 | E34: 43567 | F34: Marketing | G34: SMM mutaxassisi | H34: Senior | I34: Toshkent | J34: 16340000 | K34: 4 | L34: 5 | M34: 15 | N34: Ofis | P34: Yo'q
A35: EMP-0034 | B35: Behruz Umarov | C35: Erkak | D35: 36169 | E35: 46155 | F35: Sotuv | G35: Hudud menejeri | H35: Junior | I35: Toshkent | J35: 3500000 | K35: 3 | L35: 3 | M35: 18 | N35: Gibrid | O35: O'rta maxsus | P35: Yo'q
A36: EMP-0035 | B36: Nigora Saidova | C36: Ayol | D36: 34317 | E36: 44016 | F36: IT | G36: Dasturchi | H36: Middle | I36: Toshkent | J36: 7940000 | K36: 5 | L36: 2 | M36: 15 | N36: Ofis | O36: Bakalavr | P36: Yo'q
A37: EMP-0036 | B37: Gulnora Hasanova | C37: Ayol | D37: 34286 | E37: 43664 | F37: Sotuv | G37: Hudud menejeri | H37: Junior | I37: Toshkent | J37: 4810000 | K37: 3 | L37: 2 | M37: 28 | N37: Masofaviy | O37: O'rta maxsus | P37: Yo'q
A38: EMP-0037 | B38: Dilshod Nazarov | C38: Erkak | D38: 36320 | E38: 45845 | F38: Mijozlar xizmati | G38: Call-markaz operatori | H38: Senior | I38: Toshkent | J38: 9980000 | K38: 3 | L38: 3 | M38: 14 | N38: Ofis | O38: Bakalavr | P38: Yo'q
A39: EMP-0038 | B39: Nodira Hasanova | C39: Ayol | D39: 37714 | E39: 45976 | F39: Marketing | G39: Marketolog | H39: Junior | I39: Toshkent | J39: 4060000 | K39: 3 | L39: 4 | M39: 11 | N39: Masofaviy | O39: Bakalavr | P39: Yo'q
A40: EMP-0039 | B40: Sevara Qodirova | C40: Ayol | D40: 32048 | E40: 43132 | F40: IT | G40: Tizim administratori | H40: Junior | I40: Buxoro | J40: 4630000 | K40: 3 | L40: 4 | M40: 12 | N40: Masofaviy | O40: Bakalavr | P40: Yo'q
...

Sheet Bolimlar
A1: Bo'lim | B1: Bo'lim rahbari | C1: Xodimlar_soni_reja
A2: Sotuv | B2: Aziz Karimov | C2: 190
A3: Marketing | B3: Dilnoza Rahimova | C3: 80
A4: IT | B4: Jasur Yusupov | C4: 110
A5: Moliya | B5: Madina Abdullayeva | C5: 70
A6: HR | B6: Nodira Tursunova | C6: 35
A7: Logistika | B7: Sardor Nazarov | C7: 125
A8: Mijozlar xizmati | B8: Shahlo Ismoilova | C8: 190

Sheet Data_Dictionary
A1: Ustun | B1: Tavsif | C1: Tur
A2: Xodim_ID | B2: Xodimning noyob raqami | C2: Matn
A3: Ism_familiya | B3: To'liq ism | C3: Matn
A4: Jins | B4: Erkak / Ayol | C4: Matn
A5: Tug'ilgan_sana | B5: Tug'ilgan sana | C5: Sana
A6: Ishga_kirgan_sana | B6: Ishga qabul qilingan sana | C6: Sana
A7: Bo'lim | B7: Ishlagan bo'limi | C7: Matn
A8: Lavozim | B8: Lavozim nomi | C8: Matn
A9: Daraja | B9: Junior / Middle / Senior | C9: Matn
A10: Shahar | B10: Ishlagan shahri | C10: Matn
A11: Oylik (so'm) | B11: Oylik maosh, so'm | C11: Son
A12: Samaradorlik_bahosi (1-5) | B12: Rahbar bahosi, 5 — eng yaxshi | C12: Butun son
... A19: Ketish_sababi | B19: Ketish sababi (faqat ketganlar uchun) | C19: Matn
